WARNING:django.request:Not Found: /favicon.ico
ERROR:root:[{'id': 1, 'name': 'Monster incorp.', 'address': 'a1', 'city': 'a2', 'postal_code': 'a3', 'administrative_unit': 'gregt regw', 'flat_number': 43, 'nip': 12345678, 'krs': 12345678, 'description': 'g rf hreh etrhrtehe', 'org_status': 0, 'rendered': False, 'mail': 'gg@gmail.com', 'owner_id': 1}]
INFO:django.utils.autoreload:C:\Users\Shurik\PycharmProjects\Old_python_project\Project\socialmerge\mergeservice\models.py changed, reloading.
WARNING:django.request:Not Found: /favicon.ico
ERROR:root:[{'id': 1, 'name': 'Monster incorp.', 'address': 'a1', 'city': 'a2', 'postal_code': 'a3', 'administrative_unit': 'gregt regw', 'flat_number': 43, 'nip': 12345678, 'krs': 12345678, 'description': 'g rf hreh etrhrtehe', 'org_status': 0, 'rendered': False, 'mail': 'gg@gmail.com', 'owner_id': 1}]
ERROR:django.request:Internal Server Error: /
Traceback (most recent call last):
  File "/usr/local/lib/python3.10/dist-packages/django/core/handlers/exception.py", line 55, in inner
    response = get_response(request)
  File "/usr/local/lib/python3.10/dist-packages/django/core/handlers/base.py", line 197, in _get_response
    response = wrapped_callback(request, *callback_args, **callback_kwargs)
  File "/usr/local/lib/python3.10/dist-packages/django/views/generic/base.py", line 84, in view
    return self.dispatch(request, *args, **kwargs)
  File "/usr/local/lib/python3.10/dist-packages/django/views/generic/base.py", line 119, in dispatch
    return handler(request, *args, **kwargs)
  File "/home/shurik/PycharmProjects/pythonProject/SM-MS/mergeservice/views.py", line 182, in get
    return render(request, 'mergeservice/main_page.html', {'grants': grants.objects.values(), 'orgs_prof': self.seperate_prof_companies(), 'orgs_non_prof': self.seperate_non_prof_companies()})
  File "/usr/local/lib/python3.10/dist-packages/django/shortcuts.py", line 24, in render
    content = loader.render_to_string(template_name, context, request, using=using)
  File "/usr/local/lib/python3.10/dist-packages/django/template/loader.py", line 61, in render_to_string
    template = get_template(template_name, using=using)
  File "/usr/local/lib/python3.10/dist-packages/django/template/loader.py", line 15, in get_template
    return engine.get_template(template_name)
  File "/usr/local/lib/python3.10/dist-packages/django/template/backends/django.py", line 34, in get_template
    return Template(self.engine.get_template(template_name), self)
  File "/usr/local/lib/python3.10/dist-packages/django/template/engine.py", line 176, in get_template
    template, origin = self.find_template(template_name)
  File "/usr/local/lib/python3.10/dist-packages/django/template/engine.py", line 158, in find_template
    template = loader.get_template(name, skip=skip)
  File "/usr/local/lib/python3.10/dist-packages/django/template/loaders/base.py", line 28, in get_template
    return Template(
  File "/usr/local/lib/python3.10/dist-packages/django/template/base.py", line 154, in __init__
    self.nodelist = self.compile_nodelist()
  File "/usr/local/lib/python3.10/dist-packages/django/template/base.py", line 200, in compile_nodelist
    return parser.parse()
  File "/usr/local/lib/python3.10/dist-packages/django/template/base.py", line 513, in parse
    raise self.error(token, e)
  File "/usr/local/lib/python3.10/dist-packages/django/template/base.py", line 511, in parse
    compiled_result = compile_func(self, token)
  File "/usr/local/lib/python3.10/dist-packages/django/template/defaulttags.py", line 968, in do_if
    nodelist = parser.parse(("endif",))
  File "/usr/local/lib/python3.10/dist-packages/django/template/base.py", line 513, in parse
    raise self.error(token, e)
  File "/usr/local/lib/python3.10/dist-packages/django/template/base.py", line 511, in parse
    compiled_result = compile_func(self, token)
  File "/usr/local/lib/python3.10/dist-packages/django/template/defaulttags.py", line 1370, in url
    raise TemplateSyntaxError(
django.template.exceptions.TemplateSyntaxError: 'url' takes at least one argument, a URL pattern name.
ERROR:root:[{'id': 1, 'name': 'Monster incorp.', 'address': 'a1', 'city': 'a2', 'postal_code': 'a3', 'administrative_unit': 'gregt regw', 'flat_number': 43, 'nip': 12345678, 'krs': 12345678, 'description': 'g rf hreh etrhrtehe', 'org_status': 0, 'rendered': False, 'mail': 'gg@gmail.com', 'owner_id': 1}]
ERROR:django.request:Internal Server Error: /
Traceback (most recent call last):
  File "/usr/local/lib/python3.10/dist-packages/django/core/handlers/exception.py", line 55, in inner
    response = get_response(request)
  File "/usr/local/lib/python3.10/dist-packages/django/core/handlers/base.py", line 197, in _get_response
    response = wrapped_callback(request, *callback_args, **callback_kwargs)
  File "/usr/local/lib/python3.10/dist-packages/django/views/generic/base.py", line 84, in view
    return self.dispatch(request, *args, **kwargs)
  File "/usr/local/lib/python3.10/dist-packages/django/views/generic/base.py", line 119, in dispatch
    return handler(request, *args, **kwargs)
  File "/home/shurik/PycharmProjects/pythonProject/SM-MS/mergeservice/views.py", line 182, in get
    return render(request, 'mergeservice/main_page.html', {'grants': grants.objects.values(), 'orgs_prof': self.seperate_prof_companies(), 'orgs_non_prof': self.seperate_non_prof_companies()})
  File "/usr/local/lib/python3.10/dist-packages/django/shortcuts.py", line 24, in render
    content = loader.render_to_string(template_name, context, request, using=using)
  File "/usr/local/lib/python3.10/dist-packages/django/template/loader.py", line 62, in render_to_string
    return template.render(context, request)
  File "/usr/local/lib/python3.10/dist-packages/django/template/backends/django.py", line 62, in render
    return self.template.render(context)
  File "/usr/local/lib/python3.10/dist-packages/django/template/base.py", line 175, in render
    return self._render(context)
  File "/usr/local/lib/python3.10/dist-packages/django/template/base.py", line 167, in _render
    return self.nodelist.render(context)
  File "/usr/local/lib/python3.10/dist-packages/django/template/base.py", line 1000, in render
    return SafeString("".join([node.render_annotated(context) for node in self]))
  File "/usr/local/lib/python3.10/dist-packages/django/template/base.py", line 1000, in <listcomp>
    return SafeString("".join([node.render_annotated(context) for node in self]))
  File "/usr/local/lib/python3.10/dist-packages/django/template/base.py", line 958, in render_annotated
    return self.render(context)
  File "/usr/local/lib/python3.10/dist-packages/django/template/defaulttags.py", line 322, in render
    return nodelist.render(context)
  File "/usr/local/lib/python3.10/dist-packages/django/template/base.py", line 1000, in render
    return SafeString("".join([node.render_annotated(context) for node in self]))
  File "/usr/local/lib/python3.10/dist-packages/django/template/base.py", line 1000, in <listcomp>
    return SafeString("".join([node.render_annotated(context) for node in self]))
  File "/usr/local/lib/python3.10/dist-packages/django/template/base.py", line 958, in render_annotated
    return self.render(context)
  File "/usr/local/lib/python3.10/dist-packages/django/template/defaulttags.py", line 472, in render
    url = reverse(view_name, args=args, kwargs=kwargs, current_app=current_app)
  File "/usr/local/lib/python3.10/dist-packages/django/urls/base.py", line 88, in reverse
    return resolver._reverse_with_prefix(view, prefix, *args, **kwargs)
  File "/usr/local/lib/python3.10/dist-packages/django/urls/resolvers.py", line 802, in _reverse_with_prefix
    raise NoReverseMatch(msg)
django.urls.exceptions.NoReverseMatch: Reverse for '' not found. '' is not a valid view function or pattern name.
ERROR:root:[{'id': 1, 'name': 'Monster incorp.', 'address': 'a1', 'city': 'a2', 'postal_code': 'a3', 'administrative_unit': 'gregt regw', 'flat_number': 43, 'nip': 12345678, 'krs': 12345678, 'description': 'g rf hreh etrhrtehe', 'org_status': 0, 'rendered': False, 'mail': 'gg@gmail.com', 'owner_id': 1}]
ERROR:root:[{'id': 1, 'name': 'Monster incorp.', 'address': 'a1', 'city': 'a2', 'postal_code': 'a3', 'administrative_unit': 'gregt regw', 'flat_number': 43, 'nip': 12345678, 'krs': 12345678, 'description': 'g rf hreh etrhrtehe', 'org_status': 0, 'rendered': False, 'mail': 'gg@gmail.com', 'owner_id': 1}]
ERROR:root:[{'id': 1, 'name': 'Monster incorp.', 'address': 'a1', 'city': 'a2', 'postal_code': 'a3', 'administrative_unit': 'gregt regw', 'flat_number': 43, 'nip': 12345678, 'krs': 12345678, 'description': 'g rf hreh etrhrtehe', 'org_status': 0, 'rendered': False, 'mail': 'gg@gmail.com', 'owner_id': 1}]
ERROR:django.request:Internal Server Error: /
Traceback (most recent call last):
  File "/usr/local/lib/python3.10/dist-packages/django/core/handlers/exception.py", line 55, in inner
    response = get_response(request)
  File "/usr/local/lib/python3.10/dist-packages/django/core/handlers/base.py", line 197, in _get_response
    response = wrapped_callback(request, *callback_args, **callback_kwargs)
  File "/usr/local/lib/python3.10/dist-packages/django/views/generic/base.py", line 84, in view
    return self.dispatch(request, *args, **kwargs)
  File "/usr/local/lib/python3.10/dist-packages/django/views/generic/base.py", line 119, in dispatch
    return handler(request, *args, **kwargs)
  File "/home/shurik/PycharmProjects/pythonProject/SM-MS/mergeservice/views.py", line 182, in get
    return render(request, 'mergeservice/main_page.html', {'grants': grants.objects.values(), 'orgs_prof': self.seperate_prof_companies(), 'orgs_non_prof': self.seperate_non_prof_companies()})
  File "/usr/local/lib/python3.10/dist-packages/django/shortcuts.py", line 24, in render
    content = loader.render_to_string(template_name, context, request, using=using)
  File "/usr/local/lib/python3.10/dist-packages/django/template/loader.py", line 62, in render_to_string
    return template.render(context, request)
  File "/usr/local/lib/python3.10/dist-packages/django/template/backends/django.py", line 62, in render
    return self.template.render(context)
  File "/usr/local/lib/python3.10/dist-packages/django/template/base.py", line 175, in render
    return self._render(context)
  File "/usr/local/lib/python3.10/dist-packages/django/template/base.py", line 167, in _render
    return self.nodelist.render(context)
  File "/usr/local/lib/python3.10/dist-packages/django/template/base.py", line 1000, in render
    return SafeString("".join([node.render_annotated(context) for node in self]))
  File "/usr/local/lib/python3.10/dist-packages/django/template/base.py", line 1000, in <listcomp>
    return SafeString("".join([node.render_annotated(context) for node in self]))
  File "/usr/local/lib/python3.10/dist-packages/django/template/base.py", line 958, in render_annotated
    return self.render(context)
  File "/usr/local/lib/python3.10/dist-packages/django/template/defaulttags.py", line 322, in render
    return nodelist.render(context)
  File "/usr/local/lib/python3.10/dist-packages/django/template/base.py", line 1000, in render
    return SafeString("".join([node.render_annotated(context) for node in self]))
  File "/usr/local/lib/python3.10/dist-packages/django/template/base.py", line 1000, in <listcomp>
    return SafeString("".join([node.render_annotated(context) for node in self]))
  File "/usr/local/lib/python3.10/dist-packages/django/template/base.py", line 958, in render_annotated
    return self.render(context)
  File "/usr/local/lib/python3.10/dist-packages/django/template/defaulttags.py", line 472, in render
    url = reverse(view_name, args=args, kwargs=kwargs, current_app=current_app)
  File "/usr/local/lib/python3.10/dist-packages/django/urls/base.py", line 88, in reverse
    return resolver._reverse_with_prefix(view, prefix, *args, **kwargs)
  File "/usr/local/lib/python3.10/dist-packages/django/urls/resolvers.py", line 802, in _reverse_with_prefix
    raise NoReverseMatch(msg)
django.urls.exceptions.NoReverseMatch: Reverse for 'company_creating' not found. 'company_creating' is not a valid view function or pattern name.
ERROR:root:[{'id': 1, 'name': 'Monster incorp.', 'address': 'a1', 'city': 'a2', 'postal_code': 'a3', 'administrative_unit': 'gregt regw', 'flat_number': 43, 'nip': 12345678, 'krs': 12345678, 'description': 'g rf hreh etrhrtehe', 'org_status': 0, 'rendered': False, 'mail': 'gg@gmail.com', 'owner_id': 1}]
ERROR:root:[{'id': 1, 'name': 'Monster incorp.', 'address': 'a1', 'city': 'a2', 'postal_code': 'a3', 'administrative_unit': 'gregt regw', 'flat_number': 43, 'nip': 12345678, 'krs': 12345678, 'description': 'g rf hreh etrhrtehe', 'org_status': 0, 'rendered': False, 'mail': 'gg@gmail.com', 'owner_id': 1}]
ERROR:root:[{'id': 1, 'name': 'Monster incorp.', 'address': 'a1', 'city': 'a2', 'postal_code': 'a3', 'administrative_unit': 'gregt regw', 'flat_number': 43, 'nip': 12345678, 'krs': 12345678, 'description': 'g rf hreh etrhrtehe', 'org_status': 0, 'rendered': False, 'mail': 'gg@gmail.com', 'owner_id': 1}]
